Workbook

Sheet FK Map
A1: S.No. | B1: Table | C1: Column | D1: Reference Table | E1: Reference Column | F1: Cardinality
A2: 1 | B2: Sales_SKU | C2: SKU Code | D2: Material Master | E2: SKU Code | F2: One to one
A3: 2 | B3: Sales_SKU | C3: plant | D3: Plants | E3: plant_code | F3: Many to one
A4: 3 | B4: Sales_SKU | C4: market_eligibility | D4: Regions | E4: region_id | F4: Many to one
A5: 4 | B5: Purchase_SKU | C5: SKU code | D5: Material Master | E5: SKU Code | F5: One to one
A6: 5 | B6: Countries | C6: region_id | D6: Regions | E6: region_id | F6: Many to one
A7: 6 | B7: Customers | C7: country_iso | D7: Countries | E7: iso_code | F7: Many to one
A8: 7 | B8: Customers | C8: customer_region_id | D8: Regions | E8: region_id | F8: Many to one
A9: 8 | B9: SLA Profiles | C9: scope_region_id | D9: Regions | E9: region_id | F9: Many to one
A10: 9 | B10: Lines | C10: plant_id | D10: Plants | E10: plant_code | F10: Many to one
A11: 10 | B11: Bins | C11: node_id | D11: Storage Nodes | E11: node_id | F11: Many to one
A12: 11 | B12: LSP Master List | C12: base_node_id | D12: Storage Nodes | E12: node_id | F12: Many to one
A13: 12 | B13: LSP Master List | C13: coverage_nodes | D13: Storage Nodes | E13: node_id | F13: Many to one
... A55: 54 | B55: Lessons | C55: Review ID | D55: Review Events | E55: Review Event ID | F55: Many to one

Sheet Material Master
A1: SKU Code (Primary Key) | B1: cas_number | C1: hazard_class | D1: shelf_life_months
A2: ESS-ACETYL-ETHACE-LM-98.5-NEAT-BULK-DST | B2: 141-78-6 | C2: Flam. Liq. 2 | D2: 24
A3: ESS-ACETYL-ETHACE-LM-98.5-NEAT-BULK-DST | B3: 141-78-6 | C3: Flam. Liq. 2 | D3: 24
A4: ESS-ACETYL-ETHACE-LM-98.5-NEAT-BULK-DST | B4: 141-78-6 | C4: Flam. Liq. 2 | D4: 24
A5: SPI-ACETYL-ACEANH-PH-98.6-NEAT-DR200_UN-MHD | B5: 108-24-7 | C5: Skin Corr. 1B | D5: 24
A6: SPI-ACETYL-ACEANH-PH-98.6-NEAT-DR200_UN-MHD | B6: 108-24-7 | C6: Skin Corr. 1B | D6: 24
A7: SPI-ACETYL-ACEANH-PH-98.6-NEAT-DR200_UN-MHD | B7: 108-24-7 | C7: Skin Corr. 1B | D7: 24
A8: SPI-ACETYL-ACE-IND-98.4-NEAT-ISO20-LTE | B8: 75-07-0 | C8: Flam. Liq. 2; Acute Tox. 3 | D8: 12
A9: SPI-ACETYL-ACE-IND-98.4-NEAT-ISO20-LTE | B9: 75-07-0 | C9: Flam. Liq. 2; Acute Tox. 3 | D9: 12
A10: SPI-ACETYL-ACE-IND-98.4-NEAT-ISO20-LTE | B10: 75-07-0 | C10: Flam. Liq. 2; Acute Tox. 3 | D10: 12
A11: ESS-ACETYL-BUTACE-TECH-98.3-NEAT-DR200-DHJ | B11: 123-86-4 | C11: Flam. Liq. 3 | D11: 24
A12: ESS-ACETYL-BUTACE-TECH-98.3-NEAT-DR200-DHJ | B12: 123-86-4 | C12: Flam. Liq. 3 | D12: 24
A13: ESS-ACETYL-BUTACE-TECH-98.3-NEAT-DR200-DHJ | B13: 123-86-4 | C13: Flam. Liq. 3 | D13: 24
... A130: RM-DIK-ET-88412 | B130: 674-82-8 | C130: Flam. Liq. 2 | D130: 12
A131: INT-KET-INS-145120 | B131: 463-51-4 | C131: Flam. Gas 1; Acute Tox. 2
A132: INT-DKD-INT-342781 | C132: Flam. Liq. 3 | D132: 12
A133: INT-ARY-INT-558903 | C133: Skin Irrit. 2 | D133: 12
A134: INT-FLR-BLK-903117 | C134: DG (Fluoro) | D134: 12
A135: RM-SUL-AC-10477 | B135: 7664-93-9 | C135: Skin Corr. 1A | D135: 36
A136: RM-HCL-32-65019 | B136: 7647-01-0 | C136: Skin Corr. 1B | D136: 24
A137: RM-NAO-CP-77811 | B137: 1310-73-2 | C137: Skin Corr. 1A | D137: 36
A138: RM-ACN-SV-33120 | B138: 75-05-8 | C138: Flam. Liq. 2 | D138: 36
A139: RM-TOL-SV-90412 | B139: 108-88-3 | C139: Flam. Liq. 2 | D139: 36
A140: RM-MEO-SV-11024 | B140: 67-56-1 | C140: Flam. Liq. 2; Acute Tox. 3 | D140: 36
A141: RM-PDH-CB-61302 | B141: 7440-05-3 | D141: 36
A142: RM-PTC-CAT-27190 | B142: 1643-19-2 | C142: Acute Tox. 4 | D142: 36
A143: PACK-DRM-HD-20001
A144: PACK-IBC-IB-10002
A145: PACK-BAG-PP-25003
A146: PACK-LIN-FX-12004
A147: PACK-SEA-DR-33005
A148: INT-ACE-ANH-772001 | B148: 108-24-7 | C148: Skin Corr. 1B | D148: 12
A149: INT-AAA-EMM-990812 | D149: 12

Sheet Sales_SKU
A1: FG_Primary Key | B1: SKU Code (FK) | C1: business_unit | D1: Product family | E1: Product Sub-group (molecule_name) | F1: Variant (grade) | G1: Spec 1 (key_specs_assay_pct) | H1: Spec 2 (key_specs_moisture_ppm) | I1: Spec 3 (key_specs_color_apha) | J1: form | K1: packaging | L1: plant (plant FK) | M1: market_eligibility (regions FK) | N1: regulatory_set_id
A2: FG01 | B2: ESS-ACETYL-ETHACE-LM-98.5-NEAT-BULK-DST | C2: Essentials | D2: ACETYL | E2: Ethyl Acetate | F2: LM | G2: 98.3 | H2: 233 | I2: 17 | J2: =IF(ISNUMBER(SEARCH("-NEAT-",Sales_SKU!$B2)),"Neat",IF(ISNUMBER(SEARCH("-PWD-",Sales_SKU!$B2)),"powder","")) -> Neat | K2: BULK | L2: DST | M2: IN | N2: REG-IN-ACETYL-LM
A3: FG02 | B3: ESS-ACETYL-ETHACE-LM-98.5-NEAT-BULK-DST | C3: Essentials | D3: ACETYL | E3: Ethyl Acetate | F3: LM | G3: 98.3 | H3: 246 | I3: 19 | J3: =IF(ISNUMBER(SEARCH("-NEAT-",Sales_SKU!$B3)),"Neat",IF(ISNUMBER(SEARCH("-PWD-",Sales_SKU!$B3)),"powder","")) -> Neat | K3: BULK | L3: DST | M3: EU | N3: REG-EU-ACETYL-LM
A4: FG03 | B4: ESS-ACETYL-ETHACE-LM-98.5-NEAT-BULK-DST | C4: Essentials | D4: ACETYL | E4: Ethyl Acetate | F4: LM | G4: 98.3 | H4: 259 | I4: 23 | J4: =IF(ISNUMBER(SEARCH("-NEAT-",Sales_SKU!$B4)),"Neat",IF(ISNUMBER(SEARCH("-PWD-",Sales_SKU!$B4)),"powder","")) -> Neat | K4: BULK | L4: DST | M4: APAC | N4: REG-APAC-ACETYL-LM
A5: FG04 | B5: SPI-ACETYL-ACEANH-PH-98.6-NEAT-DR200_UN-MHD | C5: Specialties | D5: ACETYL | E5: Acetic Anhydride | F5: PH | G5: 98.8 | H5: 139 | I5: 8 | J5: =IF(ISNUMBER(SEARCH("-NEAT-",Sales_SKU!$B5)),"Neat",IF(ISNUMBER(SEARCH("-PWD-",Sales_SKU!$B5)),"powder","")) -> Neat | K5: DR200_UN | L5: MHD | M5: IN | N5: REG-IN-ACETYL-PH
A6: FG05 | B6: SPI-ACETYL-ACEANH-PH-98.6-NEAT-DR200_UN-MHD | C6: Specialties | D6: ACETYL | E6: Acetic Anhydride | F6: PH | G6: 98.8 | H6: 51 | I6: 8 | J6: =IF(ISNUMBER(SEARCH("-NEAT-",Sales_SKU!$B6)),"Neat",IF(ISNUMBER(SEARCH("-PWD-",Sales_SKU!$B6)),"powder","")) -> Neat | K6: DR200_UN | L6: MHD | M6: EU | N6: REG-EU-ACETYL-PH
A7: FG06 | B7: SPI-ACETYL-ACEANH-PH-98.6-NEAT-DR200_UN-MHD | C7: Specialties | D7: ACETYL | E7: Acetic Anhydride | F7: PH | G7: 98.8 | H7: 64 | I7: 9 | J7: =IF(ISNUMBER(SEARCH("-NEAT-",Sales_SKU!$B7)),"Neat",IF(ISNUMBER(SEARCH("-PWD-",Sales_SKU!$B7)),"powder","")) -> Neat | K7: DR200_UN | L7: MHD | M7: APAC | N7: REG-APAC-ACETYL-PH
A8: FG07 | B8: SPI-ACETYL-ACE-IND-98.4-NEAT-ISO20-LTE | C8: Specialties | D8: ACETYL | E8: Acetaldehyde | F8: IND | G8: 98.4 | H8: 345 | I8: 22 | J8: =IF(ISNUMBER(SEARCH("-NEAT-",Sales_SKU!$B8)),"Neat",IF(ISNUMBER(SEARCH("-PWD-",Sales_SKU!$B8)),"powder","")) -> Neat | K8: ISO20 | L8: LTE | M8: IN | N8: REG-IN-ACETYL-IND
A9: FG08 | B9: SPI-ACETYL-ACE-IND-98.4-NEAT-ISO20-LTE | C9: Specialties | D9: ACETYL | E9: Acetaldehyde | F9: IND | G9: 98.4 | H9: 358 | I9: 21 | J9: =IF(ISNUMBER(SEARCH("-NEAT-",Sales_SKU!$B9)),"Neat",IF(ISNUMBER(SEARCH("-PWD-",Sales_SKU!$B9)),"powder","")) -> Neat | K9: ISO20 | L9: LTE | M9: EU | N9: REG-EU-ACETYL-IND
A10: FG09 | B10: SPI-ACETYL-ACE-IND-98.4-NEAT-ISO20-LTE | C10: Specialties | D10: ACETYL | E10: Acetaldehyde | F10: IND | G10: 98.4 | H10: 371 | I10: 17 | J10: =IF(ISNUMBER(SEARCH("-NEAT-",Sales_SKU!$B10)),"Neat",IF(ISNUMBER(SEARCH("-PWD-",Sales_SKU!$B10)),"powder","")) -> Neat | K10: ISO20 | L10: LTE | M10: APAC | N10: REG-APAC-ACETYL-IND
A11: FG10 | B11: ESS-ACETYL-BUTACE-TECH-98.3-NEAT-DR200-DHJ | C11: Essentials | D11: ACETYL | E11: Butyl Acetate | F11: TECH | G11: 98.2 | H11: 200 | I11: 14 | J11: =IF(ISNUMBER(SEARCH("-NEAT-",Sales_SKU!$B11)),"Neat",IF(ISNUMBER(SEARCH("-PWD-",Sales_SKU!$B11)),"powder","")) -> Neat | K11: DR200 | L11: DHJ | M11: IN | N11: REG-IN-ACETYL-TECH
A12: FG11 | B12: ESS-ACETYL-BUTACE-TECH-98.3-NEAT-DR200-DHJ | C12: Essentials | D12: ACETYL | E12: Butyl Acetate | F12: TECH | G12: 98.2 | H12: 213 | I12: 14 | J12: =IF(ISNUMBER(SEARCH("-NEAT-",Sales_SKU!$B12)),"Neat",IF(ISNUMBER(SEARCH("-PWD-",Sales_SKU!$B12)),"powder","")) -> Neat | K12: DR200 | L12: DHJ | M12: EU | N12: REG-EU-ACETYL-TECH
A13: FG12 | B13: ESS-ACETYL-BUTACE-TECH-98.3-NEAT-DR200-DHJ | C13: Essentials | D13: ACETYL | E13: Butyl Acetate | F13: TECH | G13: 98.2 | H13: 226 | I13: 9 | J13: =IF(ISNUMBER(SEARCH("-NEAT-",Sales_SKU!$B13)),"Neat",IF(ISNUMBER(SEARCH("-PWD-",Sales_SKU!$B13)),"powder","")) -> Neat | K13: DR200 | L13: DHJ | M13: APAC | N13: REG-APAC-ACETYL-TECH
... A121: FG120 | B121: ESS-FLUORO-FLRBLK-LM-98.9-PWD-BAG25-DHJ | C121: Essentials | D121: FLUORO | E121: Fluoro Building Block | F121: LM | G121: 98.7 | H121: 236 | I121: 20 | J121: =IF(ISNUMBER(SEARCH("-NEAT-",Sales_SKU!$B121)),"Neat",IF(ISNUMBER(SEARCH("-PWD-",Sales_SKU!$B121)),"powder","")) -> powder | K121: BAG25 | L121: DHJ | M121: APAC | N121: REG-APAC-FLUORO-LM

Sheet Purchase_SKU
A1: rm_id (Primary Key) | B1: SKU code (FK) | C1: rm_name | D1: rm_type | E1: uom | F1: storage_type | G1: storage_temp_c | H1: lead_time_days | I1: criticality | J1: approved_for_families | K1: primary_source_region_id | L1: notes
A2: RM0001 | B2: RM-ETH-AL-64175 | C2: Ethyl Alcohol (Ethanol) | D2: RAW_MATERIAL | E2: MT | F2: Tank | G2: Ambient | H2: 7 | I2: A | J2: ACETYL,DKD | K2: DOM | L2: Bulk solvent/feed; excise-controlled; illustrative
A3: RM0002 | B3: RM-AAC-GL-23011 | C3: Acetic Acid (Glacial) | D3: RAW_MATERIAL | E3: MT | F3: Tank | G3: Ambient | H3: 10 | I3: A | J3: ACETYL,DKD | K3: DOM | L3: Corrosive; dedicated SS tank; illustrative
A4: RM0003 | B4: RM-BUT-NB-51720 | C4: n-Butanol | D4: RAW_MATERIAL | E4: MT | F4: Tank | G4: Ambient | H4: 14 | I4: B | J4: ACETYL | K4: APAC | L4: Flammable; used for butyl acetate; illustrative
A5: RM0004 | B5: RM-ETL-AC-11804 | C5: Ethyl Acetate (Solvent grade) | D5: RAW_MATERIAL | E5: MT | F5: Tank | G5: Ambient | H5: 12 | I5: B | J5: ACETYL | K5: DOM | L5: Purchased solvent for blends/cleaning; illustrative
A6: RM0005 | B6: RM-MTH-AA-40218 | C6: Methacrylic Acid | D6: RAW_MATERIAL | E6: KG | F6: Drum/IBC | G6: Ambient | H6: 28 | I6: A | J6: ACETYL | K6: EU | L6: Inhibitor present; check MEHQ ppm; illustrative
A7: RM0006 | B7: RM-ANI-LN-90355 | C7: Aniline | D7: RAW_MATERIAL | E7: KG | F7: Drum/IBC | G7: Ambient | H7: 30 | I7: A | J7: ARYLIDE | K7: DOM | L7: Toxic; COA required per batch; illustrative
A8: RM0007 | B8: RM-PCA-AN-77210 | C8: p-Chloroaniline | D8: RAW_MATERIAL | E8: KG | F8: Bag | G8: Ambient | H8: 35 | I8: A | J8: ARYLIDE | K8: APAC | L8: Solid; store dry; sieve before charge; illustrative
A9: RM0008 | B9: RM-OAN-AS-55102 | C9: o-Anisidine | D9: RAW_MATERIAL | E9: KG | F9: Drum/IBC | G9: Ambient | H9: 32 | I9: B | J9: ARYLIDE | K9: EU | L9: Light sensitive; nitrogen blanket preferred; illustrative
A10: RM0009 | B10: RM-DIK-ET-88412 | C10: Diketene | D10: RAW_MATERIAL | E10: KG | F10: Drum/IBC | G10: 2-8 | H10: 21 | I10: A | J10: DKD,ACETYL | K10: DOM | L10: Refrigerated storage; moisture sensitive; illustrative
A11: RM0010 | B11: INT-KET-INS-145120 | C11: Ketene (in-situ) | D11: INTERMEDIATE | E11: KG | F11: On-site Generation | G11: N/A | H11: 0 | I11: A | J11: DKD,ACETYL | K11: DOM | L11: Generated on demand; no inventory; illustrative
A12: RM0011 | B12: INT-DKD-INT-342781 | C12: DKD Intermediate (Crude) | D12: INTERMEDIATE | E12: KG | F12: Drum/IBC | G12: Ambient | H12: 3 | I12: B | J12: DKD | K12: DOM | L12: Internal transfer; QC release required; illustrative
A13: RM0012 | B13: INT-ARY-INT-558903 | C13: Arylide Intermediate (Wet cake) | D13: INTERMEDIATE | E13: KG | F13: Bag | G13: Ambient | H13: 2 | I13: B | J13: ARYLIDE | K13: DOM | L13: Moist solid; process within 48h; illustrative
... A29: RM0028 | B29: INT-AAA-EMM-990812 | C29: AAEM Precursor (Stabilized) | D29: INTERMEDIATE | E29: KG | F29: Drum/IBC | G29: Ambient | H29: 4 | I29: B | J29: ACETYL | K29: DOM | L29: Stabilized intermediate; check inhibitor; illustrative

Sheet Regions
A1: region_id (Primary Key) | B1: region_name | C1: type | D1: active | E1: notes
A2: DOM | B2: India (Domestic) | C2: COUNTRY | D2: TRUE | E2: Domestic sales; GST invoicing; standard road lanes.
A3: EU | B3: European Union | C3: BLOC | D3: TRUE | E3: REACH/CLP compliance; SDS in local languages; DG-capable sea lanes.
A4: AMER | B4: Americas | C4: REGION | D4: TRUE | E4: US/LatAm exports; TSCA alignment; longer lead times via ocean freight.
A5: APAC | B5: Asia Pacific | C5: REGION | D5: TRUE | E5: APAC export hub; varied local registrations; mixed sea/road lanes.
A6: MEA | B6: Middle East & Africa | C6: REGION | D6: TRUE | E6: Often DG documentation required; bank LC common; temperature exposure risk.
A7: ROW | B7: Rest of World | C7: REGION | D7: TRUE | E7: Catch-all region for ad-hoc exports; validate local regulatory needs per shipment.

Sheet Countries
A1: country_id (Primary Key) | B1: country_name | C1: type | D1: iso_code | E1: region_id (FK) | F1: active | G1: notes
A2: IND | B2: India | C2: COUNTRY | D2: IN | E2: DOM | F2: TRUE | G2: Home market; GST/road lanes.
A3: DEU | B3: Germany | C3: COUNTRY | D3: DE | E3: EU | F3: TRUE | G3: EU; REACH/CLP aligned.
A4: FRA | B4: France | C4: COUNTRY | D4: FR | E4: EU | F4: TRUE | G4: EU; DG documentation common.
A5: ITA | B5: Italy | C5: COUNTRY | D5: IT | E5: EU | F5: TRUE | G5: EU; port lead times vary.
A6: ESP | B6: Spain | C6: COUNTRY | D6: ES | E6: EU | F6: TRUE | G6: EU; distributor network.
A7: NLD | B7: Netherlands | C7: COUNTRY | D7: NL | E7: EU | F7: TRUE | G7: EU hub; Rotterdam.
A8: BEL | B8: Belgium | C8: COUNTRY | D8: BE | E8: EU | F8: TRUE | G8: EU chemicals; strict SDS.
A9: POL | B9: Poland | C9: COUNTRY | D9: PL | E9: EU | F9: TRUE | G9: EU; growing demand.
A10: SWE | B10: Sweden | C10: COUNTRY | D10: SE | E10: EU | F10: TRUE | G10: EU; DG sea lanes.
A11: DNK | B11: Denmark | C11: COUNTRY | D11: DK | E11: EU | F11: TRUE | G11: EU; DG sea lanes.
A12: AUT | B12: Austria | C12: COUNTRY | D12: AT | E12: EU | F12: TRUE | G12: EU; inland trucking.
A13: CZE | B13: Czech Republic | C13: COUNTRY | D13: CZ | E13: EU | F13: TRUE | G13: EU; labeling compliance.
... A53: IRN | B53: Iran | C53: COUNTRY | D53: IR | E53: MEA | F53: FALSE | G53: Restricted market; illustrative inactive.

Sheet Customers
A1: customer_id (Primary Key) | B1: customer_name | C1: customer_type | D1: industry | E1: industry_code | F1: customer_region_id (FK-style) | G1: country_iso (FK) | H1: city | I1: currency | J1: channel | K1: risk_rating | L1: status | M1: gst_vat_id | N1: key_account_manager | O1: created_date
A2: CUS0001 | B2: GreenField Pharma GmbH | C2: B2B | D2: Pharmaceuticals | E2: PHARMA | F2: DOM | G2: IN | H2: Ahmedabad | I2: INR | J2: Direct | K2: C | L2: Active | M2: TAX-IN-499676 | N2: Team-Strategic | O2: 45994
A3: CUS0002 | B3: Keystone Pigments Co. Ltd | C3: B2B | D3: Adhesives | E3: ADH | F3: CN | G3: CN | H3: Shanghai | I3: CNY | J3: Distributor | K3: A | L3: Active | M3: TAX-CN-943121 | N3: Team-Intl | O3: 46191
A4: CUS0003 | B4: Aurum Agro S.A. | C4: B2B | D4: Industrial Solvents | E4: SOLV | F4: DOM | G4: IN | H4: Mumbai | I4: INR | J4: Distributor | K4: C | L4: Active | M4: TAX-IN-696397 | N4: Team-South | O4: 46070
A5: CUS0004 | B5: BluePeak Agro Ltd | C5: B2B | D5: Pigments | E5: PIGM | F5: US | G5: US | H5: Newark | I5: USD | J5: Distributor | K5: B | L5: Active | M5: TAX-US-215769 | N5: Team-Intl | O5: 45589
A6: CUS0005 | B6: Keystone Coatings S.A. | C6: B2B | D6: Inks & Coatings | E6: INKS | F6: DOM | G6: IN | H6: Gurgaon | I6: INR | J6: Distributor | K6: B | L6: Active | M6: TAX-IN-979970 | N6: Team-West | O6: 45404
A7: CUS0006 | B7: Sapphire Pharma NV | C7: B2B | D7: Industrial Solvents | E7: SOLV | F7: CN | G7: CN | H7: Shenzhen | I7: CNY | J7: Direct | K7: A | L7: Active | M7: TAX-CN-490679 | N7: Team-Strategic | O7: 45521
A8: CUS0007 | B8: Sterling Solvents GmbH | C8: B2B | D8: Adhesives | E8: ADH | F8: DOM | G8: IN | H8: Gurgaon | I8: INR | J8: Direct | K8: A | L8: Active | M8: TAX-IN-987820 | N8: Team-South | O8: 45758
A9: CUS0008 | B9: Nimbus Pigments S.A. | C9: B2B | D9: Agrochemicals | E9: AGRO | F9: US | G9: US | H9: Newark | I9: USD | J9: Direct | K9: B | L9: Active | M9: TAX-US-840961 | N9: Team-Intl | O9: 46292
A10: CUS0009 | B10: Silverline Pharma Inc. | C10: B2B | D10: Packaging | E10: PKG | F10: DOM | G10: IN | H10: Ahmedabad | I10: INR | J10: Direct | K10: B | L10: Active | M10: TAX-IN-700729 | N10: Team-South | O10: 45897
A11: CUS0010 | B11: Keystone Coatings Co. Ltd | C11: B2B | D11: Inks & Coatings | E11: INKS | F11: EU | G11: FR | H11: Lyon | I11: EUR | J11: Distributor | K11: B | L11: Active | M11: TAX-FR-255209 | N11: Team-Intl | O11: 45884
A12: CUS0011 | B12: Nimbus Packaging NV | C12: B2B | D12: Pigments | E12: PIGM | F12: EU | G12: SE | H12: Barcelona | I12: EUR | J12: Distributor | K12: A | L12: Active | M12: TAX-SE-766346 | N12: Team-Intl | O12: 46356
A13: CUS0012 | B13: Sterling Agro LLP | C13: B2B | D13: Adhesives | E13: ADH | F13: DOM | G13: IN | H13: Chennai | I13: INR | J13: Distributor | K13: B | L13: Prospect | M13: TAX-IN-731425 | N13: Team-Strategic | O13: 46281
... A101: CUS0100 | B101: Atlas Pigments LLP | C101: B2B | D101: Pigments | E101: PIGM | F101: EU | G101: DE | H101: Warsaw | I101: EUR | J101: Direct | K101: C | L101: Active | M101: TAX-DE-234001 | N101: Team-Intl | O101: 46341

Sheet SLA Profiles
A1: sla_id (Primary Key) | B1: sla_name | C1: scope_region_id (FK) | D1: applicable_channels | E1: applicable_families | F1: incoterms_scope | G1: service_window_cutoff_local | H1: service_days | I1: dispatch_lead_time_days (min) | J1: dispatch_lead_time_days (max) | K1: Handover at | L1: delivery_window_days (min) | M1: delivery_window_days (max) | N1: otif_target_pct | O1: ot_time_tolerance | P1: in_full_target_pct | Q1: fill_rate_target_pct | R1: backorder_resolution_days | S1: quote_tat_hours | T1: order_ack_tat_hours | U1: documentation_requirements | V1: documentation_accuracy_pct | W1: pod_submission_hours | X1: claims_response_business_days | Y1: claims_closure_business_days | Z1: temperature_control | AA1: dg_class_handling | AB1: min_order_quantity | AC1: packaging_constraints | AD1: penalty_credit_logic | AE1: review_frequency | AF1: effective_from | AG1: effective_to | AH1: status
A2: SLA_STD_DOM_T1 | B2: Domestic Standard T1 (Bulk Liquids) | C2: DOM | D2: Direct,Distributor | E2: ACETYL,DKD | F2: EXW/FCA | G2: 14:00 | H2: Mon-Sat | I2: 1 | J2: 2 | K2: Plant gate | L2: 1 | M2: 3 | N2: 94 | O2: +/-1 day | P2: 97 | Q2: 96 | R2: 5 | S2: 8 | T2: 4 | U2: COA,Invoice,Ewaybill | V2: 99.5 | W2: 48 | X2: 3 | Y2: 10 | Z2: Ambient | AA2: DG allowed (where applicable) | AB2: 2000 KG | AC2: BULK,ISO20,IBC1KL | AD2: 1% credit if OTIF < target (monthly) on eligible orders | AE2: Quarterly | AF2: 2026-01-01 | AH2: Active
A3: SLA_STD_DOM_T2 | B3: Domestic Priority T2 (Drums/IBCs) | C3: DOM | D3: Direct,Distributor | E3: ACETYL,DKD,ARYLIDE | F3: EXW/FCA | G3: 16:00 | H3: Mon-Sat | I3: 0 | J3: 1 | K3: Plant gate | L3: 1 | M3: 2 | N3: 96 | O3: +/-0 day | P3: 98 | Q3: 97 | R3: 3 | S3: 6 | T3: 2 | U3: COA,Invoice,Ewaybill,UN Pack Cert (if DG) | V3: 99.7 | W3: 36 | X3: 2 | Y3: 7 | Z3: Ambient | AA3: DG allowed | AB3: 500 KG | AC3: DR200,DR200_UN,IBC1KL | AD3: 2% credit on freight line if OTIF < target (monthly) | AE3: Monthly | AF3: 2026-01-01 | AH3: Active
A4: SLA_STD_DOM_T3 | B4: Domestic Economy T3 (Powders) | C4: DOM | D4: Distributor | E4: ARYLIDE,FLUORO | F4: EXW | G4: 12:00 | H4: Mon-Fri | I4: 2 | J4: 4 | K4: Plant gate | L4: 2 | M4: 5 | N4: 92 | O4: +/-1 day | P4: 96 | Q4: 95 | R4: 7 | S4: 12 | T4: 6 | U4: COA,Invoice | V4: 99 | W4: 72 | X4: 4 | Y4: 15 | Z4: Ambient | AA4: DG by exception | AB4: 1000 KG | AC4: BAG25 only | AD4: No penalties; service credits only for documented failures above 3% of orders | AE4: Semi-Annual | AF4: 2026-01-01 | AH4: Active
A5: SLA_EXPORT_EU_T1 | B5: Export EU T1 (REACH-ready) | C5: EU | D5: Export-Direct,Distributor | E5: ACETYL,DKD,ARYLIDE | F5: FOB/CIF/CIP | G5: 13:00 | H5: Mon-Fri | I5: 3 | J5: 5 | K5: Port (Nhava Sheva/Mundra) | L5: 14 | M5: 21 | N5: 94 | O5: +/-2 days | P5: 97 | Q5: 96 | R5: 10 | S5: 24 | T5: 12 | U5: COA,Invoice,Packing List,SDS,REACH docs,BL | V5: 99.5 | W5: 120 | X5: 5 | Y5: 20 | Z5: Ambient | AA5: DG allowed (IMO) | AB5: 10 MT | AC5: ISO20,Flexitank,DR200_UN | AD5: 1% credit on invoice value if OTIF < target (quarterly) for contract orders | AE5: Quarterly | AF5: 2026-01-01 | AH5: Active
A6: SLA_EXPORT_US_T1_D | B6: Export US T1 (DG capable - Direct) | C6: AMER | D6: Export-Direct | E6: ACETYL,DKD | F6: FOB/CIF | G6: 13:00 | H6: Mon-Fri | I6: 3 | J6: 6 | K6: Port (Nhava Sheva) | L6: 18 | M6: 28 | N6: 93 | O6: +/-3 days | P6: 96 | Q6: 95 | R6: 12 | S6: 24 | T6: 12 | U6: COA,Invoice,Packing List,SDS,TSCA statement,BL | V6: 99.3 | W6: 168 | X6: 5 | Y6: 25 | Z6: Ambient | AA6: DG allowed (IMO) | AB6: 10 MT | AC6: ISO20,DR200_UN | AD6: 2% credit on ocean freight component if OTIF < target (quarterly) | AE6: Quarterly | AF6: 2026-01-01 | AH6: Active
A7: SLA_EXPORT_US_T1_P | B7: Export US T1 (Pharma/High Purity) | C7: AMER | D7: Export-Direct | E7: ACETYL | F7: CIP/DDP (case by case) | G7: 12:00 | H7: Mon-Fri | I7: 2 | J7: 4 | K7: Port + Forwarder handoff | L7: 14 | M7: 24 | N7: 95 | O7: +/-2 days | P7: 98 | Q7: 97 | R7: 8 | S7: 16 | T7: 8 | U7: COA,Invoice,Packing List,SDS,TSCA,Allergen/Pharma statement,BL | V7: 99.7 | W7: 120 | X7: 4 | Y7: 18 | Z7: 46061 | AA7: Non-DG preferred | AB7: 5 MT | AC7: DR200_UN,IBC1KL | AD7: Service credit 1% if documentation accuracy < target; OTIF credits per contract | AE7: Monthly | AF7: 2026-01-01 | AH7: Active
A8: SLA_EXPORT_APAC_T1_D | B8: Export APAC T1 (SEA lanes) | C8: APAC | D8: Export-Direct,Distributor | E8: ACETYL,DKD,FLUORO | F8: FOB/CIF | G8: 14:00 | H8: Mon-Fri | I8: 2 | J8: 5 | K8: Port (Nhava Sheva/Mundra) | L8: 10 | M8: 18 | N8: 94 | O8: +/-2 days | P8: 97 | Q8: 96 | R8: 8 | S8: 18 | T8: 8 | U8: COA,Invoice,Packing List,SDS,BL | V8: 99.2 | W8: 96 | X8: 4 | Y8: 15 | Z8: Ambient | AA8: DG allowed (IMO) | AB8: 5 MT | AC8: ISO20,DR200_UN,IBC1KL | AD8: 0.5% credit if OTIF < target (quarterly) for annual contracts | AE8: Quarterly | AF8: 2026-01-01 | AH8: Active
A9: SLA_EXPORT_APAC_T1_P | B9: Export APAC T1 (Powders) | C9: APAC | D9: Export-Direct,Distributor | E9: ARYLIDE,FLUORO | F9: FOB/CIF | G9: 12:00 | H9: Mon-Fri | I9: 3 | J9: 6 | K9: Port (Nhava Sheva/Mundra) | L9: 12 | M9: 20 | N9: 92 | O9: +/-3 days | P9: 96 | Q9: 95 | R9: 10 | S9: 24 | T9: 12 | U9: COA,Invoice,Packing List,SDS,BL | V9: 99 | W9: 120 | X9: 5 | Y9: 20 | Z9: Ambient | AA9: DG where required | AB9: 3 MT | AC9: BAG25,IBC1KL | AD9: No penalties for port delays; credit applies only for documentation failures | AE9: Semi-Annual | AF9: 2026-01-01 | AH9: Active
A10: SLA_EXPORT_ROW_T2_D | B10: Export ROW T2 (DG/Remote - Direct) | C10: MEA | D10: Export-Direct | E10: ACETYL,DKD,FLUORO | F10: FOB/CFR/CIF | G10: 11:00 | H10: Mon-Fri | I10: 4 | J10: 8 | K10: Port (Nhava Sheva) | L10: 20 | M10: 35 | N10: 90 | O10: +/-4 days | P10: 95 | Q10: 94 | R10: 15 | S10: 30 | T10: 12 | U10: COA,Invoice,Packing List,SDS,BL,Legalization (if required) | V10: 98.8 | W10: 240 | X10: 7 | Y10: 30 | Z10: Ambient | AA10: DG allowed (IMO) | AB10: 10 MT | AC10: ISO20,DR200_UN | AD10: Credits capped at 0.5% of invoice; exclusions for force majeure/port congestion | AE10: Annual | AF10: 2026-01-01 | AH10: Active
A11: SLA_EXPORT_ROW_T2_P | B11: Export ROW T2 (Project/Small lots) | C11: MEA | D11: Distributor | E11: ARYLIDE,FLUORO | F11: EXW/FCA/FOB | G11: 10:00 | H11: Mon-Fri | I11: 5 | J11: 10 | K11: Plant gate / Port | L11: 25 | M11: 45 | N11: 90 | O11: +/-5 days | P11: 95 | Q11: 94 | R11: 20 | S11: 36 | T11: 24 | U11: COA,Invoice,Packing List,SDS | V11: 98.5 | W11: 240 | X11: 8 | Y11: 35 | Z11: Ambient | AA11: DG by exception | AB11: 1000 KG | AC11: BAG25,DR200_UN | AD11: No penalties; review service gaps in QBR and agree corrective actions | AE11: Annual | AF11: 2026-01-01 | AG11: 2026-12-31 | AH11: Planned

Sheet Orders
A1: Mean
A2: St Deviation (%)
A3: Total per month / No. of entries | B3: 180
A4: Order ID (Primary Key) | B4: Order Type | C4: Order Date | D4: Customer ID (FK) | E4: To WH ID | F4: Payment Terms | G4: Order Status
A5: ORD202602-0001 | B5: Sales Order | C5: 2026-02-01 | D5: CUS0001 | F5: Advance | G5: Delivered
A6: ORD202602-0002 | B6: Sales Order | C6: 2026-02-02 | D6: CUS0002 | F6: Net 15 | G6: Delivered
A7: ORD202602-0003 | B7: Sales Order | C7: 2026-02-03 | D7: CUS0003 | F7: Advance | G7: Delivered
A8: ORD202602-0004 | B8: Sales Order | C8: 2026-02-04 | D8: CUS0004 | F8: Net 30 | G8: Delivered
A9: ORD202602-0005 | B9: Sales Order | C9: 2026-02-05 | D9: CUS0005 | F9: Net 15 | G9: Shipped
A10: ORD202602-0006 | B10: Sales Order | C10: 2026-02-06 | D10: CUS0006 | F10: Net 30 | G10: Shipped
A11: ORD202602-0007 | B11: Transfer Order | C11: 2026-02-07 | E11: TNK_EUR_RTM | F11: Net 30 | G11: Confirmed
A12: ORD202602-0008 | B12: Sales Order | C12: 2026-02-08 | D12: CUS0008 | F12: Net 15 | G12: Delivered
A13: ORD202602-0009 | B13: Sales Order | C13: 2026-02-09 | D13: CUS0009 | F13: Net 30 | G13: Delivered
A14: ORD202602-0010 | B14: Sales Order | C14: 2026-02-10 | D14: CUS0010 | F14: Net 15 | G14: Delivered
A15: ORD202602-0011 | B15: Sales Order | C15: 2026-02-11 | D15: CUS0011 | F15: Advance | G15: Shipped
A16: ORD202602-0012 | B16: Sales Order | C16: 2026-02-12 | D16: CUS0012 | F16: Net 30 | G16: Shipped
A17: ORD202602-0013 | B17: Sales Order | C17: 2026-02-13 | D17: CUS0013 | F17: Net 15 | G17: Shipped
A18: ORD202602-0014 | B18: Transfer Order | C18: 2026-02-14 | E18: TNK_EUR_ANT | F18: Net 30 | G18: Confirmed
A19: ORD202602-0015 | B19: Sales Order | C19: 2026-02-15 | D19: CUS0015 | F19: Advance | G19: Confirmed
A20: ORD202602-0016 | B20: Sales Order | C20: 2026-02-16 | D20: CUS0016 | F20: Net 30 | G20: Delivered
A21: ORD202602-0017 | B21: Sales Order | C21: 2026-02-17 | D21: CUS0017 | F21: Advance | G21: Delivered
A22: ORD202602-0018 | B22: Sales Order | C22: 2026-02-18 | D22: CUS0018 | F22: Net 15 | G22: Shipped
A23: ORD202602-0019 | B23: Sales Order | C23: 2026-02-19 | D23: CUS0019 | F23: Advance | G23: Shipped
A24: ORD202602-0020 | B24: Sales Order | C24: 2026-02-20 | D24: CUS0020 | F24: Net 30 | G24: Shipped
A25: ORD202602-0021 | B25: Transfer Order | C25: 2026-02-21 | E25: TNK_EUR_GEN | F25: Net 30 | G25: Confirmed
A26: ORD202602-0022 | B26: Sales Order | C26: 2026-02-22 | D26: CUS0022 | F26: Advance | G26: Confirmed
A27: ORD202602-0023 | B27: Sales Order | C27: 2026-02-23 | D27: CUS0023 | F27: Advance | G27: Confirmed
A28: ORD202602-0024 | B28: Sales Order | C28: 2026-02-24 | D28: CUS0024 | F28: Net 30 | G28: Shipped
A29: ORD202602-0025 | B29: Sales Order | C29: 2026-02-25 | D29: CUS0025 | F29: Net 30 | G29: Shipped
A30: ORD202602-0026 | B30: Sales Order | C30: 2026-02-26 | D30: CUS0026 | F30: Net 30 | G30: Shipped
A31: ORD202602-0027 | B31: Sales Order | C31: 2026-02-27 | D31: CUS0027 | F31: Net 15 | G31: Confirmed
A32: ORD202602-0028 | B32: Transfer Order | C32: 2026-02-28 | E32: WH_IN_WEST_BHI | F32: Net 30 | G32: Confirmed
A33: ORD202602-0029 | B33: Sales Order | C33: 2026-02-01 | D33: CUS0029 | F33: Net 15 | G33: Shipped
A34: ORD202602-0030 | B34: Sales Order | C34: 2026-02-02 | D34: CUS0030 | F34: Advance | G34: Confirmed
A35: ORD202602-0031 | B35: Sales Order | C35: 2026-02-03 | D35: CUS0031 | F35: Advance | G35: Delivered
A36: ORD202602-0032 | B36: Sales Order | C36: 2026-02-04 | D36: CUS0032 | F36: Net 30 | G36: Delivered
A37: ORD202602-0033 | B37: Sales Order | C37: 2026-02-05 | D37: CUS0033 | F37: Net 30 | G37: Delivered
A38: ORD202602-0034 | B38: Sales Order | C38: 2026-02-06 | D38: CUS0034 | F38: Net 30 | G38: Delivered
A39: ORD202602-0035 | B39: Transfer Order | C39: 2026-02-07 | E39: WH_IN_GUJ_AHD | F39: Net 30 | G39: Delivered
A40: ORD202602-0036 | B40: Sales Order | C40: 2026-02-08 | D40: CUS0036 | F40: Advance | G40: Shipped
...

Sheet Order_Line Items
A1: Mean
A2: St Deviation (%)
A3: Total per month / No. of entries | B3: 216
A4: Order Line Item (Primary Key) | B4: Order_id (FK) | C4: SLA Profile ID (FK) | D4: Delivery_by_date | E4: Requirement Status | F4: Fulfilled by WH ID (WH ID FK) | G4: SKU ID (FK) | H4: Quantity (MT) | I4: Unit Price (USD) | J4: Value (USD) | K4: Forecast ID (FK)
A5: OLI202602-0001 | B5: ORD202602-0001 | C5: SLA_STD_DOM_T1 | D5: 2026-02-09 | E5: Fulfilled | F5: WH_IN_NORTH_BAW | G5: ESS-ACETYL-ACEANH-IND-98.8-NEAT-BULK-MHD | H5: 101.01 | I5: 1076.43 | J5: 108731.54 | K5: FC202602-DOM-ACETYL
A6: OLI202602-0002 | B6: ORD202602-0002 | C6: SLA_EXPORT_ROW_T2_D | D6: 2026-02-26 | E6: Fulfilled | F6: WH_UAE_SHJ | G6: ESS-ACETYL-ACEANH-PH-99.7-NEAT-ISO20-DHJ | H6: 106.95 | I6: 1082.43 | J6: 115763.95 | K6: FC202602-APAC-ACETYL
A7: OLI202602-0003 | B7: ORD202602-0003 | C7: SLA_STD_DOM_T1 | D7: 2026-02-10 | E7: Fulfilled | F7: WH_IN_WEST_BHI | G7: ESS-ACETYL-BUTACE-PH-98.5-NEAT-ISO20-MHD | H7: 92.21 | I7: 1282.15 | J7: 118222.68 | K7: FC202602-DOM-ACETYL
A8: OLI202602-0004 | B8: ORD202602-0004 | C8: SLA_EXPORT_US_T1_D | D8: 2026-03-01 | E8: Fulfilled | F8: CFS_IN_NHAV | G8: ESS-ACETYL-AAEM-INK-99.7-NEAT-IBC1KL-LTE | H8: 95.46 | I8: 1237.57 | J8: 118134.89 | K8: FC202602-AMER-ACETYL
A9: OLI202602-0005 | B9: ORD202602-0005 | C9: SLA_STD_DOM_T2 | D9: 2026-02-15 | E9: In Transit | F9: WH_IN_GUJ_AHD | G9: SPI-ACETYL-MAA-TECH-98.7-NEAT-DR200-LTE | H9: 79.9 | I9: 1130.54 | J9: 90333.06 | K9: FC202602-DOM-ACETYL
A10: OLI202602-0006 | B10: ORD202602-0006 | C10: SLA_EXPORT_ROW_T2_P | D10: 2026-02-28 | E10: In Transit | F10: WH_UAE_SHJ | G10: SPI-ARYLIDE-ARYINT-TECH-98.4-PWD-BAG25-DST | H10: 107.28 | I10: 1848.85 | J10: 198347.1 | K10: FC202602-APAC-ARYLIDE
A11: OLI202602-0007 | B11: ORD202602-0007 | C11: SLA_STD_DOM_T2 | D11: 2026-02-17 | E11: Planned | F11: TNK_EUR_RTM | G11: ESS-ACETYL-EAA-IND-98.3-NEAT-IBC1KL-MHD | H11: 90.14 | I11: 1146.69 | J11: 103361.82 | K11: FC202602-DOM-ACETYL
A12: OLI202602-0008 | B12: ORD202602-0008 | C12: SLA_EXPORT_US_T1_D | D12: 2026-03-03 | E12: Fulfilled | F12: WH_US_EAST_NJ | G12: ESS-ACETYL-MAA-LM-98.4-NEAT-IBC1KL-DST | H12: 97.7 | I12: 999.77 | J12: 97674.11 | K12: FC202602-AMER-ACETYL
A13: OLI202602-0009 | B13: ORD202602-0009 | C13: SLA_STD_DOM_T3 | D13: 2026-02-18 | E13: Fulfilled | F13: WH_IN_WEST_BHI | G13: SPI-FLUORO-FLRBLK-LM-99.0-PWD-BAG25-DHJ | H13: 88.24 | I13: 2119.56 | J13: 187029.67 | K13: FC202602-DOM-FLUORO
A14: OLI202602-0010 | B14: ORD202602-0010 | C14: SLA_EXPORT_EU_T1 | D14: 2026-03-01 | E14: Fulfilled | F14: TNK_EUR_RTM | G14: ESS-ACETYL-ACEANH-IND-98.8-NEAT-BULK-MHD | H14: 87.14 | I14: 1018.86 | J14: 88787.15 | K14: FC202602-EU-ACETYL
A15: OLI202602-0011 | B15: ORD202602-0011 | C15: SLA_EXPORT_EU_T1 | D15: 2026-03-08 | E15: In Transit | F15: TNK_EUR_RTM | G15: ESS-DKD-DKDINT-LM-98.0-NEAT-DR200-MHD | H15: 92.41 | I15: 1240.89 | J15: 114674.38 | K15: FC202602-EU-DKD
A16: OLI202602-0012 | B16: ORD202602-0012 | C16: SLA_STD_DOM_T2 | D16: 2026-02-21 | E16: In Transit | F16: WH_IN_SOUTH_HYD | G16: SPI-ACETYL-EAA-IND-99.2-NEAT-DR200-MHD | H16: 95.89 | I16: 1296.85 | J16: 124349.92 | K16: FC202602-DOM-ACETYL
... A220: OLI202602-0216 | B220: ORD202602-0055 | C220: SLA_EXPORT_US_T1_D | D220: 2026-03-23 | E220: In Transit | F220: WH_US_EAST_NJ | G220: ESS-ACETYL-ETHACE-LM-98.5-NEAT-BULK-DST | H220: 106.28 | I220: 1217.12 | J220: 129355.51 | K220: FC202602-AMER-ACETYL

Sheet Signals
A1: No restriction on number of signals
A2: Signal ID (Primary Key) | B2: Source | C2: Topic headline | D2: Description | E2: Sentiment Score | F2: Confidence | G2: Detected On_Date | H2: Signal Type | I2: Forecast ID (FK) | J2: Exception ID (FK)
A3: SIG202602-0001 | B3: News (ICIS) | C3: European ethanol tightness lifts solvent feedstock costs | D3: ICIS highlights tighter EU ethanol availability; monitor import parity and consider advancing March purchases for ACETYL chain. Review TNK_EUR_RTM replenishment plan. | E3: 0.18 | F3: 0.78 | G3: 2026-02-01T06:45:00.000Z | H3: forecast input | I3: FC202602-EU-ACETYL
A4: SIG202602-0002 | B4: Finance note (FX/credit) | C4: INR volatility may impact import cost for methacrylic acid | D4: FX desk flags INR weakness vs EUR; update landed cost assumptions for AAEM-related inputs and validate customer price pass-through. | E4: -0.12 | F4: 0.74 | G4: 2026-02-01T11:20:00.000Z | H4: forecast input | I4: FC202602-DOM-ACETYL
A5: SIG202602-0003 | B5: Internal memo (Plant Ops) | C5: Mahad esterification train running stable at higher throughputs | D5: Ops note indicates Train 2 sustained rates; opportunity to pull forward domestic dispatches if WH_IN_WEST_BHI capacity allows. | E5: 0.22 | F5: 0.83 | G5: 2026-02-02T03:10:00.000Z | H5: forecast input | I5: FC202602-DOM-ACETYL
A6: SIG202602-0004 | B6: LSP bulletin | C6: JNPT congestion warning for DG containers this week | D6: Carrier bulletin warns of gate-in delays at CFS_IN_NHAV; prioritize documentation readiness and consider earlier cut-offs for export lots. | E6: -0.35 | F6: 0.86 | G6: 2026-02-02T09:55:00.000Z | H6: exception | J6: EXC202602-0001
A7: SIG202602-0005 | B7: Customer call note | C7: US coatings customer requests additional DR200_UN availability | D7: Customer indicates preference for UN drums for Q2; validate drum supply and align allocation from WH_US_EAST_NJ for smoother deliveries. | E7: 0.09 | F7: 0.69 | G7: 2026-02-03T15:05:00.000Z | H7: forecast input | I7: FC202602-AMER-ACETYL
A8: SIG202602-0006 | B8: News (S&P Global Platts) | C8: Freight rates soften on Asia-Europe lane in February | D8: Platts notes modest decline in spot container rates; reassess CIF offers for APAC customers and update forecast margin assumptions. | E8: 0.11 | F8: 0.77 | G8: 2026-02-03T04:30:00.000Z | H8: forecast input | I8: FC202602-APAC-ACETYL
A9: SIG202602-0007 | B9: Internal email (Sales) | C9: Distributor asking for extended credit on acetyl solvents | D9: Sales email suggests higher credit exposure; recommend Advance terms for risk-rated C accounts until payments normalize. | E9: -0.28 | F9: 0.71 | G9: 2026-02-04T08:40:00.000Z | H9: exception | J9: EXC202602-0002
A10: SIG202602-0008 | B10: News (ICIS) | C10: Acetic acid spot prices firm on planned maintenance | D10: ICIS reports planned turnarounds; consider locking domestic contracts and updating FC202602-DOM-ACETYL assumptions for March-April. | E10: 0.26 | F10: 0.84 | G10: 2026-02-04T12:15:00.000Z | H10: forecast input | I10: FC202602-DOM-ACETYL
A11: SIG202602-0009 | B11: Internal memo (Plant Ops) | C11: Lote fluoro suite scheduling constraint for DG packaging | D11: Ops flags limited DG packing slots; stagger FLUORO dispatches and reserve bagging windows for BAG25 lots. | E11: -0.14 | F11: 0.8 | G11: 2026-02-05T05:05:00.000Z | H11: exception | J11: EXC202602-0003
A12: SIG202602-0010 | B12: Customer call note | C12: EU pigment customer expects stronger demand for arylide intermediates | D12: Customer indicates higher pulls; propose increasing TNK_EUR_ANT safety stock and adjust FC202602-EU-ARYLIDE upward. | E12: 0.31 | F12: 0.76 | G12: 2026-02-05T13:35:00.000Z | H12: forecast input | I12: FC202602-EU-ARYLIDE
A13: SIG202602-0011 | B13: LSP bulletin | C13: Rotterdam terminal slot availability reduced for ISO tanks | D13: Terminal operator signals fewer ISO20 slots; pre-book arrivals and avoid bunching shipments into TNK_EUR_RTM. | E13: -0.21 | F13: 0.82 | G13: 2026-02-06T07:20:00.000Z | H13: exception | J13: EXC202602-0004
A14: SIG202602-0012 | B14: Internal email (Sales) | C14: Domestic inks customer requests higher assay EAA for reformulation | D14: Customer needs tighter assay; align allocations to PH/INK grades and update forecast mix for ACETYL-EAA in DOM. | E14: 0.12 | F14: 0.67 | G14: 2026-02-06T10:50:00.000Z | H14: forecast input | I14: FC202602-DOM-ACETYL
A15: SIG202602-0013 | B15: News (S&P Global Platts) | C15: US Gulf petrochemical rail delays may extend inland deliveries | D15: Platts mentions rail congestion; increase delivery buffers for Midwest and consider stocking WH_US_MID_CHI earlier. | E15: -0.19 | F15: 0.73 | G15: 2026-02-07T02:25:00.000Z | H15: exception | J15: EXC202602-0005
A16: SIG202602-0014 | B16: Finance note (FX/credit) | C16: Customer credit downgrade flagged for one EU distributor | D16: Credit team recommends tightening terms for the account; shift to Net 15 or Advance for EU orders until review completes. | E16: -0.33 | F16: 0.79 | G16: 2026-02-07T14:10:00.000Z | H16: exception | J16: EXC202602-0006
A17: SIG202602-0015 | B17: News (ICIS) | C17: Butanol availability steady; no near-term supply disruption | D17: Market commentary suggests stable n-butanol; keep BUTACE forecast assumptions unchanged for February. | E17: 0.05 | F17: 0.7 | G17: 2026-02-08T06:05:00.000Z | H17: forecast input | I17: FC202602-DOM-ACETYL
A18: SIG202602-0016 | B18: Internal memo (Plant Ops) | C18: DKD ester line yields improved after catalyst optimization | D18: Ops reports better yields; potential to lift DKD availability for export without increasing feed. Update FC202602-EU-DKD accordingly. | E18: 0.27 | F18: 0.88 | G18: 2026-02-08T11:55:00.000Z | H18: forecast input | I18: FC202602-EU-DKD
A19: SIG202602-0017 | B19: LSP bulletin | C19: Sharjah bonded warehouse adding DG segregation inspections | D19: New inspection step may add 1–2 days dwell; build buffer for MEA shipments routed via WH_UAE_SHJ. | E19: -0.16 | F19: 0.81 | G19: 2026-02-09T09:15:00.000Z | H19: exception | J19: EXC202602-0007
A20: SIG202602-0018 | B20: Internal email (Sales) | C20: Inquiry surge from APAC for bulk ethyl acetate ISO tanks | D20: Sales sees more ISO20 RFQs; pre-allocate ISO tanks and update FC202602-APAC-ACETYL volume expectations. | E20: 0.24 | F20: 0.72 | G20: 2026-02-09T13:45:00.000Z | H20: forecast input | I20: FC202602-APAC-ACETYL
A21: SIG202602-0019 | B21: Customer call note | C21: Domestic pharma customer requests expedited delivery for acetic anhydride | D21: Customer needs earlier delivery; check WH_IN_GUJ_AHD availability and prioritize dispatch under SLA_STD_DOM_T2. | E21: 0.08 | F21: 0.66 | G21: 2026-02-10T05:40:00.000Z | H21: exception | J21: EXC202602-0008
A22: SIG202602-0020 | B22: News (ICIS) | C22: EU REACH enforcement focus on SDS accuracy for solvents | D22: ICIS compliance note; run SDS/documentation audit for EU lots staged at TNK_EUR_GEN and TNK_EUR_RTM. | E22: -0.08 | F22: 0.75 | G22: 2026-02-10T12:30:00.000Z | H22: exception | J22: EXC202602-0009
A23: SIG202602-0021 | B23: Internal memo (Plant Ops) | C23: Planned maintenance window proposed for Mahad AA unit mid-March | D23: Ops proposes maintenance; consider building buffer inventory in February and updating March forecast for ACETYL-ACEANH. | E23: -0.1 | F23: 0.9 | G23: 2026-02-11T04:05:00.000Z | H23: forecast input | I23: FC202602-DOM-ACETYL
A24: SIG202602-0022 | B24: Finance note (FX/credit) | C24: Ocean insurance premiums inch up for DG cargo to EU | D24: Insurers signal surcharge for DG; incorporate into EU landed cost model for FLUORO and selected solvents. | E24: -0.06 | F24: 0.68 | G24: 2026-02-11T16:15:00.000Z | H24: forecast input | I24: FC202602-EU-FLUORO
A25: SIG202602-0023 | B25: LSP bulletin | C25: Antwerp terminal weekend cut-off changes for DG documentation | D25: Updated cut-offs may affect documentation sequencing; align export paperwork earlier for TNK_EUR_ANT receipts. | E25: -0.15 | F25: 0.77 | G25: 2026-02-12T07:35:00.000Z | H25: exception | J25: EXC202602-0010
A26: SIG202602-0024 | B26: Internal email (Sales) | C26: Distributor reports slower payments in North India coatings cluster | D26: Collections risk increasing; recommend Advance for new orders routed via WH_IN_NORTH_BAW until stabilization. | E26: -0.22 | F26: 0.73 | G26: 2026-02-12T10:05:00.000Z | H26: exception | J26: EXC202602-0011
A27: SIG202602-0025 | B27: News (S&P Global Platts) | C27: China demand uptick for specialty blocks amid inventory restocking | D27: Platts indicates restocking; consider incremental FLUORO volumes routed via APAC lanes and update FC202602-APAC-FLUORO. | E27: 0.29 | F27: 0.78 | G27: 2026-02-13T02:50:00.000Z | H27: forecast input | I27: FC202602-APAC-FLUORO
A28: SIG202602-0026 | B28: Customer call note | C28: US customer asks for COA turnaround within 24 hours | D28: Customer expects faster COA dispatch; ensure lab release timing aligns with SLA_EXPORT_US_T1_P and staging at CFS_IN_NHAV. | E28: 0.07 | F28: 0.62 | G28: 2026-02-13T17:20:00.000Z | H28: exception | J28: EXC202602-0012
A29: SIG202602-0027 | B29: Internal memo (Plant Ops) | C29: VOC abatement audit passed; no restrictions for bulk solvent loading | D29: Audit outcome positive; supports higher bulk load plan for Feb at MHD and export staging via CFS_IN_NHAV. | E29: 0.2 | F29: 0.85 | G29: 2026-02-14T06:30:00.000Z | H29: forecast input | I29: FC202602-DOM-ACETYL
A30: SIG202602-0028 | B30: News (ICIS) | C30: Diketene logistics constrained; cold-chain slots limited | D30: ICIS notes chilled storage scarcity; confirm 2-8°C capacity at LTE and plan receipts earlier to avoid stockouts. | E30: -0.18 | F30: 0.81 | G30: 2026-02-14T12:05:00.000Z | H30: forecast input | I30: FC202602-DOM-DKD
A31: SIG202602-0029 | B31: LSP bulletin | C31: US East warehouse labor shortages may slow unloading | D31: 3PL warns of slower receiving at WH_US_EAST_NJ; route some replenishments to WH_US_MID_CHI if feasible. | E31: -0.17 | F31: 0.76 | G31: 2026-02-15T09:40:00.000Z | H31: exception | J31: EXC202602-0013
A32: SIG202602-0030 | B32: Internal email (Sales) | C32: EU customer requests smaller lots; more DR200_UN shipments | D32: Shift toward drums increases handling; reserve DG pallet slots at TNK_EUR_RTM and adjust packaging mix forecast. | E32: 0.04 | F32: 0.7 | G32: 2026-02-15T14:25:00.000Z | H32: forecast input | I32: FC202602-EU-ACETYL
A33: SIG202602-0031 | B33: News (S&P Global Platts) | C33: Middle East buyers negotiating lower solvent prices | D33: Platts reports softer MEA pricing; protect margins via freight optimization and monitor WH_UAE_SHJ throughput. | E33: -0.11 | F33: 0.69 | G33: 2026-02-16T03:55:00.000Z | H33: forecast input | I33: FC202602-MEA-ACETYL
A34: SIG202602-0032 | B34: Customer call note | C34: Domestic adhesive customer requests weekly deliveries to reduce storage | D34: Customer wants more frequent drops; validate route capacity from WH_IN_WEST_BHI and consolidate with nearby accounts. | E34: 0.06 | F34: 0.61 | G34: 2026-02-16T11:10:00.000Z | H34: forecast input | I34: FC202602-DOM-ACETYL
A35: SIG202602-0033 | B35: Internal memo (Plant Ops) | C35: Powder bagging line dust collection maintenance scheduled | D35: Bagging downtime expected; pre-pack ARYLIDE lots and avoid late-Feb BAG25 commitments. | E35: -0.2 | F35: 0.87 | G35: 2026-02-17T05:15:00.000Z | H35: exception | J35: EXC202602-0014
A36: SIG202602-0034 | B36: Finance note (FX/credit) | C36: Customer payment improved; consider restoring Net 30 selectively | D36: Credit team notes improvement for select accounts; allow Net 30 for A-rated customers while keeping C on Advance. | E36: 0.1 | F36: 0.65 | G36: 2026-02-18T09:05:00.000Z | H36: forecast input | I36: FC202602-DOM-ACETYL
A37: SIG202602-0035 | B37: LSP bulletin | C37: Genoa terminal revises hazardous cargo documentation checklist | D37: New checklist may cause document rework; ensure SDS/IMO declarations are complete before TNK_EUR_GEN receipt. | E37: -0.13 | F37: 0.8 | G37: 2026-02-19T07:00:00.000Z | H37: exception | J37: EXC202602-0015
A38: SIG202602-0036 | B38: News (ICIS) | C38: Acetaldehyde handling advisory following regional incident | D38: ICIS safety note; re-verify handling SOPs and UN drum integrity for ACE shipments through WH_IN_GUJ_AHD. | E38: -0.09 | F38: 0.73 | G38: 2026-02-20T04:45:00.000Z | H38: exception | J38: EXC202602-0016
A39: SIG202602-0037 | B39: Internal email (Sales) | C39: APAC distributor proposes annual contract for DKD intermediates | D39: Opportunity to lock volumes; align with LTE DKD capacity and update FC202602-APAC-DKD baseline assumptions. | E39: 0.23 | F39: 0.72 | G39: 2026-02-21T13:25:00.000Z | H39: forecast input | I39: FC202602-APAC-DKD
A40: SIG202602-0038 | B40: Customer call note | C40: EU customer asks for REACH dossier reference in shipping docs | D40: Ensure documentation packet includes REACH references; stage compliant packs at TNK_EUR_ANT to avoid clearance delays. | E40: 0.02 | F40: 0.6 | G40: 2026-02-23T08:10:00.000Z | H40: exception | J40: EXC202602-0017
...

Sheet Forecasts
A1: Mean | B1: =AVERAGE(F5:F28) -> 3201.875
A2: St Deviation (%) | B2: 0.05
A3: Total per month / No. of entries | B3: 24
A4: Forecast ID (Primary Key) | B4: Demand Region ID (FK) | C4: Forecast Date | D4: Forecast Horizon | E4: Product Family | F4: Quantity | G4: S&OP Event ID (FK)
A5: FC-DOM-ACETYL | B5: DOM | C5: 46112 | D5: Monthly | E5: ACETYL | F5: 5700 | G5: SOP202603-DOM
A6: FC-EU-ACETYL | B6: EU | C6: 46112 | D6: Monthly | E6: ACETYL | F6: 5415 | G6: SOP202603-EU
A7: FC-AMER-ACETYL | B7: AMER | C7: 46112 | D7: Monthly | E7: ACETYL | F7: 5130 | G7: SOP202603-AMER
A8: FC-APAC-ACETYL | B8: APAC | C8: 46112 | D8: Monthly | E8: ACETYL | F8: 4845 | G8: SOP202603-APAC
A9: FC-MEA-ACETYL | B9: MEA | C9: 46112 | D9: Monthly | E9: ACETYL | F9: 3420 | G9: SOP202603-MEA
A10: FC-ROW-ACETYL | B10: ROW | C10: 46112 | D10: Monthly | E10: ACETYL | F10: 2280 | G10: SOP202603-ROW
A11: FC-DOM-DKD | B11: DOM | C11: 46112 | D11: Monthly | E11: DKD | F11: 5650 | G11: SOP202603-DOM
A12: FC-EU-DKD | B12: EU | C12: 46112 | D12: Monthly | E12: DKD | F12: 5367.5 | G12: SOP202603-EU
A13: FC-AMER-DKD | B13: AMER | C13: 46112 | D13: Monthly | E13: DKD | F13: 5085 | G13: SOP202603-AMER
A14: FC-APAC-DKD | B14: APAC | C14: 46112 | D14: Monthly | E14: DKD | F14: 4802.5 | G14: SOP202603-APAC
A15: FC-MEA-DKD | B15: MEA | C15: 46112 | D15: Monthly | E15: DKD | F15: 3390 | G15: SOP202603-MEA
A16: FC-ROW-DKD | B16: ROW | C16: 46112 | D16: Monthly | E16: DKD | F16: 2260 | G16: SOP202603-ROW
... A28: FC-ROW-FLUORO | B28: ROW | C28: 46112 | D28: Monthly | E28: FLUORO | F28: 720 | G28: SOP202603-ROW

Sheet SOP Events
A1: S&OP Event ID (Primary Key) | B1: Frequency | C1: Horizon | D1: Region Scope (Region ID FK) | E1: Date | F1: Minutes
A2: SOP202601-DOM | B2: Monthly | C2: 1M | D2: DOM | E2: 2026-01-15T18:30:00.000Z | F2: Illustrative monthly S&OP (DOM)
A3: SOP202601-EU | B3: Monthly | C3: 1M | D3: EU | E3: 2026-01-16T18:30:00.000Z | F3: Illustrative monthly S&OP (EU)
A4: SOP202601-AMER | B4: Monthly | C4: 1M | D4: AMER | E4: 2026-01-17T18:30:00.000Z | F4: Illustrative monthly S&OP (AMER)
A5: SOP202601-APAC | B5: Monthly | C5: 1M | D5: APAC | E5: 2026-01-14T18:30:00.000Z | F5: Illustrative monthly S&OP (APAC)
A6: SOP202602-DOM | B6: Monthly | C6: 1M | D6: DOM | E6: 2026-02-15T18:30:00.000Z | F6: Illustrative monthly S&OP (DOM)
A7: SOP202602-EU | B7: Monthly | C7: 1M | D7: EU | E7: 2026-02-16T18:30:00.000Z | F7: Illustrative monthly S&OP (EU)
A8: SOP202602-AMER | B8: Monthly | C8: 1M | D8: AMER | E8: 2026-02-17T18:30:00.000Z | F8: Illustrative monthly S&OP (AMER)
A9: SOP202602-APAC | B9: Monthly | C9: 1M | D9: APAC | E9: 2026-02-14T18:30:00.000Z | F9: Illustrative monthly S&OP (APAC)
A10: SOP202603-DOM | B10: Monthly | C10: 1M | D10: DOM | E10: 2026-03-15T18:30:00.000Z | F10: Illustrative monthly S&OP (DOM)
A11: SOP202603-EU | B11: Monthly | C11: 1M | D11: EU | E11: 2026-03-16T18:30:00.000Z | F11: Illustrative monthly S&OP (EU)
A12: SOP202603-AMER | B12: Monthly | C12: 1M | D12: AMER | E12: 2026-03-17T18:30:00.000Z | F12: Illustrative monthly S&OP (AMER)
A13: SOP202603-APAC | B13: Monthly | C13: 1M | D13: APAC | E13: 2026-03-14T18:30:00.000Z | F13: Illustrative monthly S&OP (APAC)

Sheet Capacity Reservations
A1: Mean | B1: 378.87
A2: St Deviation (%) | B2: 0.05
A3: Total per month / No. of entries | B3: 60
A4: Capacity Reservation ID (Primary Key) | B4: S&OP Event ID (FK) | C4: Product Family | D4: Line ID (FK) | E4: Reserved Quantity (MT) | F4: Planned Start Date | G4: Planned End Date | H4: Status
A5: CR202603-0001 | B5: SOP202603-DOM | C5: ACETYL | D5: LINE_MHD_EA_TRAIN1 | E5: 397.12 | F5: 46082 | G5: 46085 | H5: Draft
A6: CR202603-0002 | B6: SOP202603-EU | C6: ACETYL | D6: LINE_MHD_AA_ANHY | E6: 388.64 | F6: 46084 | G6: 46088 | H6: Draft
A7: CR202603-0003 | B7: SOP202603-AMER | C7: ACETYL | D7: LINE_MHD_SOL_BLEND | E7: 365.84 | F7: 46086 | G7: 46091 | H7: Draft
A8: CR202603-0004 | B8: SOP202602-DOM | C8: ACETYL | D8: LINE_MHD_EA_TRAIN1 | E8: 362.13 | F8: 46088 | G8: 46094 | H8: Draft
A9: CR202603-0005 | B9: SOP202602-EU | C9: ACETYL | D9: LINE_MHD_AA_ANHY | E9: 382.95 | F9: 46090 | G9: 46097 | H9: Draft
A10: CR202603-0006 | B10: SOP202602-AMER | C10: ACETYL | D10: LINE_MHD_SOL_BLEND | E10: 397.79 | F10: 46092 | G10: 46095 | H10: Draft
A11: CR202603-0007 | B11: SOP202603-DOM | C11: ACETYL | D11: LINE_MHD_EA_TRAIN1 | E11: 384.91 | F11: 46094 | G11: 46098 | H11: Draft
A12: CR202603-0008 | B12: SOP202603-EU | C12: ACETYL | D12: LINE_MHD_AA_ANHY | E12: 363.19 | F12: 46096 | G12: 46101 | H12: Draft
A13: CR202603-0009 | B13: SOP202603-AMER | C13: ACETYL | D13: LINE_MHD_SOL_BLEND | E13: 364.44 | F13: 46098 | G13: 46104 | H13: Draft
A14: CR202603-0010 | B14: SOP202602-DOM | C14: ACETYL | D14: LINE_MHD_EA_TRAIN1 | E14: 386.83 | F14: 46100 | G14: 46107 | H14: Draft
A15: CR202603-0011 | B15: SOP202602-EU | C15: ACETYL | D15: LINE_MHD_AA_ANHY | E15: 397.56 | F15: 46102 | G15: 46105 | H15: Draft
A16: CR202603-0012 | B16: SOP202602-AMER | C16: ACETYL | D16: LINE_MHD_SOL_BLEND | E16: 380.91 | F16: 46104 | G16: 46108 | H16: Draft
... A64: CR202603-0060 | B64: SOP202602-APAC | C64: DKD | D64: LINE_LTE_FLR_BLOCK200 | E64: 360.45 | F64: 46088 | G64: 46095 | H64: Approved

Sheet Material Requirements Plan
A1: Mean | B1: 159.12
A2: St Deviation (%) | B2: 0.1
A3: Total per month / No. of entries | B3: 150
A4: MRP ID (Primary Key) | B4: Capacity Reservation ID (FK) | C4: product_family | D4: SKU Code (FK) | E4: gross_requirement_qty | F4: onhand_qty | G4: scheduled_receipts_qty | H4: net_requirement_qty | I4: uom | J4: std_lead_time_days | K4: recommended_order_release_date | L4: priority | M4: notes
A5: MRP202603-0001 | B5: CR202603-0001 | C5: ACETYL | D5: RM-ETH-AL-64197 | E5: 213.18 | F5: 38.18 | G5: 7.91 | H5: =MAX(0,E5-F5-G5) -> 167.09 | I5: MT | J5: 8 | K5: 46074 | L5: Medium | M5: ACETYL input RM-ETH-AL-64197; align procurement to March runs; illustrative.
A6: MRP202603-0002 | B6: CR202603-0002 | C6: ACETYL | D6: RM-ETH-AL-64219 | E6: 241.01 | F6: 38.74 | G6: 46.34 | H6: =MAX(0,E6-F6-G6) -> 155.93 | I6: MT | J6: 9 | K6: 46074 | L6: Medium | M6: ACETYL input RM-ETH-AL-64219; align procurement to March runs; illustrative.
A7: MRP202603-0003 | B7: CR202603-0003 | C7: ACETYL | D7: RM-SUL-AC-10477 | E7: 242.45 | F7: 18.47 | G7: 47.59 | H7: =MAX(0,E7-F7-G7) -> 176.39 | I7: MT | J7: 5 | K7: 46079 | L7: Medium | M7: ACETYL input RM-SUL-AC-10477; align procurement to March runs; illustrative.
A8: MRP202603-0004 | B8: CR202603-0004 | C8: ACETYL | D8: RM-ETH-AL-64175 | E8: 185.4 | F8: 7.56 | G8: 6.47 | H8: =MAX(0,E8-F8-G8) -> 171.37 | I8: MT | J8: 7 | K8: 46078 | L8: Medium | M8: ACETYL input RM-ETH-AL-64175; align procurement to March runs; illustrative.
A9: MRP202603-0005 | B9: CR202603-0005 | C9: ACETYL | D9: RM-ETH-AL-64197 | E9: 235.34 | F9: 63.83 | G9: 6.98 | H9: =MAX(0,E9-F9-G9) -> 164.53 | I9: MT | J9: 8 | K9: 46078 | L9: Medium | M9: ACETYL input RM-ETH-AL-64197; align procurement to March runs; illustrative.
A10: MRP202603-0006 | B10: CR202603-0006 | C10: ACETYL | D10: RM-ETH-AL-64197 | E10: 183.23 | F10: 10.03 | G10: 14.36 | H10: =MAX(0,E10-F10-G10) -> 158.84 | I10: MT | J10: 8 | K10: 46079 | L10: Medium | M10: ACETYL input RM-ETH-AL-64197; align procurement to March runs; illustrative.
A11: MRP202603-0007 | B11: CR202603-0007 | C11: ACETYL | D11: RM-AAC-GL-23011 | E11: 226.02 | F11: 40.36 | G11: 11.3 | H11: =MAX(0,E11-F11-G11) -> 174.36 | I11: MT | J11: 10 | K11: 46078 | L11: Medium | M11: ACETYL input RM-AAC-GL-23011; align procurement to March runs; illustrative.
A12: MRP202603-0008 | B12: CR202603-0008 | C12: DKD | D12: INT-KET-674828 | E12: 252.93 | F12: 52.28 | G12: 36.73 | H12: =MAX(0,E12-F12-G12) -> 163.92 | I12: MT | J12: 0 | K12: 46089 | L12: Medium | M12: DKD input INT-KET-674828; align procurement to March runs; illustrative.
A13: MRP202603-0009 | B13: CR202603-0009 | C13: ACETYL | D13: RM-BUT-NB-51720 | E13: 245.79 | F13: 60.01 | G13: 0.52 | H13: =MAX(0,E13-F13-G13) -> 185.26 | I13: MT | J13: 14 | K13: 46076 | L13: Medium | M13: ACETYL input RM-BUT-NB-51720; align procurement to March runs; illustrative.
A14: MRP202603-0010 | B14: CR202603-0010 | C14: ACETYL | D14: RM-ETH-AL-64197 | E14: 245.63 | F14: 65.97 | G14: 2.73 | H14: =MAX(0,E14-F14-G14) -> 176.93 | I14: MT | J14: 8 | K14: 46083 | L14: Medium | M14: ACETYL input RM-ETH-AL-64197; align procurement to March runs; illustrative.
A15: MRP202603-0011 | B15: CR202603-0011 | C15: DKD | D15: INT-KET-674828 | E15: 220.07 | F15: 26.28 | G15: 40.67 | H15: =MAX(0,E15-F15-G15) -> 153.12 | I15: MT | J15: 0 | K15: 46092 | L15: Medium | M15: DKD input INT-KET-674828; align procurement to March runs; illustrative.
A16: MRP202603-0012 | B16: CR202603-0012 | C16: ACETYL | D16: RM-NAO-CP-77811 | E16: 212.33 | F16: 6.66 | G16: 42.23 | H16: =MAX(0,E16-F16-G16) -> 163.44 | I16: MT | J16: 8 | K16: 46085 | L16: Medium | M16: ACETYL input RM-NAO-CP-77811; align procurement to March runs; illustrative.
... A154: MRP202603-0150 | B154: CR202603-0030 | C154: ACETYL | D154: RM-ETH-AL-64241 | E154: 125.22 | F154: 32.01 | G154: 35.08 | H154: =MAX(0,E154-F154-G154) -> 58.13 | I154: MT | J154: 10 | K154: 46081 | L154: Low | M154: ACETYL input RM-ETH-AL-64241; align procurement to March runs; illustrative.

Sheet Production Plan
A1: Mean
A2: St Deviation (%)
A3: Total per month / No. of entries | B3: 100
A4: Production Plan ID (PK) | B4: Capacity Reservations (FK) | C4: SKU ID (FK) | D4: Line ID (FK) | E4: Planned Start | F4: Planned End | G4: Required Quantity | H4: Estimated Scrappage (%) | I4: Quality Defect Rate (%) | J4: Planned Quantity | K4: Status
A5: PP202603-0001 | B5: CR202603-0001 | C5: ESS-ACETYL-ETHACE-LM-98.5-NEAT-BULK-DST | D5: LINE_MHD_EA_TRAIN2 | E5: 46082 | F5: 46082 | G5: 322.54 | H5: 0.029427372 | I5: 0.012078417 | J5: 330 | K5: Completed
A6: PP202603-0002 | B6: CR202603-0002 | C6: SPI-ACETYL-ACEANH-PH-98.6-NEAT-DR200_UN-MHD | D6: LINE_MHD_AA_ANHY | E6: 46083 | F6: 46085 | G6: 315.09 | H6: 0.024456604 | I6: 0.0065603031 | J6: 330 | K6: Completed
A7: PP202603-0003 | B7: CR202603-0003 | C7: SPI-DKD-DKDINT-IND-98.4-NEAT-ISO20-DHJ | D7: LINE_LTE_DKD_ESTER2 | E7: 46084 | F7: 46084 | G7: 41.73 | H7: 0.028126867 | I7: 0.024144046 | J7: 43.56 | K7: Completed
A8: PP202603-0004 | B8: CR202603-0004 | C8: ESS-ACETYL-BUTACE-TECH-98.3-NEAT-DR200-DHJ | D8: LINE_MHD_BA_BATCH1 | E8: 46085 | F8: 46088 | G8: 323.46 | H8: 0.023440115 | I8: 0.010597471 | J8: 330 | K8: Completed
A9: PP202603-0005 | B9: CR202603-0005 | C9: ESS-ACETYL-MAA-LM-98.4-NEAT-IBC1KL-DST | D9: LINE_MHD_EA_TRAIN1 | E9: 46085 | F9: 46085 | G9: 317.9 | H9: 0.012010283 | I9: 0.015989966 | J9: 330 | K9: Completed
A10: PP202603-0006 | B10: CR202603-0006 | C10: SPI-ACETYL-EAA-IND-99.2-NEAT-DR200-MHD | D10: LINE_MHD_EA_TRAIN1 | E10: 46087 | F10: 46090 | G10: 229.34 | H10: 0.025018376 | I10: 0.012875562 | J10: 232.39 | K10: Completed
A11: PP202603-0007 | B11: CR202603-0007 | C11: ESS-ACETYL-AAEM-TECH-98.8-NEAT-BULK-LTE | D11: LINE_MHD_AAEM_REACT1 | E11: 46088 | F11: 46090 | G11: 205.17 | H11: 0.02003091 | I11: 0.023945339 | J11: 215.21 | K11: Completed
A12: PP202603-0008 | B12: CR202603-0008 | C12: SPI-ACETYL-ETHACE-TECH-99.9-NEAT-BULK-LTE | D12: LINE_MHD_EA_TRAIN2 | E12: 46088 | F12: 46088 | G12: 275.34 | H12: 0.0029222421 | I12: 0.01513302 | J12: 282.47 | K12: Completed
A13: PP202603-0009 | B13: CR202603-0009 | C13: ESS-ACETYL-ACEANH-TECH-98.1-NEAT-ISO20-DHJ | D13: LINE_MHD_AA_ANHY | E13: 46090 | F13: 46091 | G13: 213.42 | H13: 0.0059754162 | I13: 0.02383883 | J13: 220.46 | K13: Completed
A14: PP202603-0010 | B14: CR202603-0010 | C14: ESS-ACETYL-ACE-TECH-98.8-NEAT-DR200_UN-DST | D14: LINE_MHD_EA_TRAIN1 | E14: 46090 | F14: 46091 | G14: 268.25 | H14: 0.015674906 | I14: 0.013564058 | J14: 277.93 | K14: Completed
A15: PP202603-0011 | B15: CR202603-0011 | C15: ESS-ACETYL-BUTACE-IND-98.3-NEAT-ISO20-MHD | D15: LINE_MHD_BA_BATCH1 | E15: 46090 | F15: 46093 | G15: 251 | H15: 0.012155138 | I15: 0.026021618 | J15: 255.03 | K15: Released
A16: PP202603-0012 | B16: CR202603-0012 | C16: SPI-ACETYL-MAA-TECH-98.7-NEAT-DR200-LTE | D16: LINE_MHD_EA_TRAIN1 | E16: 46091 | F16: 46091 | G16: 264.48 | H16: 0.011472411 | I16: 0.0026256883 | J16: 271.77 | K16: Completed
... A104: PP202603-0100 | B104: CR202603-0040 | C104: ESS-ACETYL-ACEANH-IND-98.8-NEAT-BULK-MHD | D104: LINE_MHD_AA_ANHY | E104: 46088 | F104: 46090 | G104: 231.3 | H104: 0.0029671446 | I104: 0.023461791 | J104: 238.83 | K104: Completed
J105: =SUM(J5:J104) -> 22277.42

Sheet Purchase Requisitions
A1: Mean | B1: 64.98
A2: Std Dev | B2: 5%
A3: Total per month / No. of entries | B3: 360
A4: PR Line ID (PK) | B4: Production Plan ID (FK) | C4: Requisition Date | D4: SKU_id (FK) | E4: Quantity | F4: Need by Date | G4: Status
A5: PR202603-0001 | B5: PP202603-0001 | C5: 2026-03-07 | D5: RM-OAN-AS-55102 | E5: 65.63 | F5: 2026-03-14 | G5: Rfx released
A6: PR202603-0002 | B6: PP202603-0001 | C6: 2026-03-13 | D6: RM-PDH-CB-61302 | E6: 62.38 | F6: 2026-03-22 | G6: Rfx released
A7: PR202603-0003 | B7: PP202603-0001 | C7: 2026-03-19 | D7: INT-ACE-ANH-772001 | E7: 66.28 | F7: 2026-03-30 | G7: Rfx released
A8: PR202603-0004 | B8: PP202603-0001 | C8: 2026-03-25 | D8: RM-ETL-AC-11804 | E8: 63.03 | F8: 2026-04-07 | G8: Rfx released
A9: PR202603-0005 | B9: PP202603-0002 | C9: 2026-03-31 | D9: RM-HCL-32-65019 | E9: 66.93 | F9: 2026-04-15 | G9: Rfx released
A10: PR202603-0006 | B10: PP202603-0002 | C10: 2026-03-06 | D10: INT-KET-674828 | E10: 63.68 | F10: 2026-03-12 | G10: PO Issued
A11: PR202603-0007 | B11: PP202603-0002 | C11: 2026-03-12 | D11: RM-ETH-AL-64197 | E11: 67.58 | F11: 2026-03-20 | G11: PO Issued
A12: PR202603-0008 | B12: PP202603-0002 | C12: 2026-03-18 | D12: RM-PCA-AN-77210 | E12: 64.33 | F12: 2026-03-28 | G12: PO Issued
A13: PR202603-0009 | B13: PP202603-0003 | C13: 2026-03-24 | D13: RM-TOL-SV-90412 | E13: 68.23 | F13: 2026-04-05 | G13: PO Issued
A14: PR202603-0010 | B14: PP202603-0003 | C14: 2026-03-30 | D14: INT-ARY-INT-558903 | E14: 64.98 | F14: 2026-04-13 | G14: PO Issued
A15: PR202603-0011 | B15: PP202603-0003 | C15: 2026-03-05 | D15: RM-AAC-GL-23011 | E15: 61.73 | F15: 2026-03-10 | G15: PO Issued
A16: PR202603-0012 | B16: PP202603-0003 | C16: 2026-03-11 | D16: RM-SUL-AC-10477 | E16: 65.63 | F16: 2026-03-18 | G16: GRN Issued
... A364: PR202603-0360 | B364: PP202603-0100 | C364: 2026-03-22 | D364: INT-KET-INS-145120 | E364: 64.33 | F364: 2026-04-01 | G364: Rfx released

Sheet Plants
A1: plant_code (Primary Key) | B1: plant_name | C1: city | D1: district | E1: state | F1: country | G1: latitude | H1: longitude | I1: business_unit | J1: operating_status | K1: iso_certifications | L1: responsible_care | M1: port_proximity_km | N1: storage_tankage_kl | O1: hazardous_waste_facility | P1: ehs_notes | Q1: effective_from | R1: status | S1: notes
A2: MHD | B2: Mahad Manufacturing Complex | C2: Mahad | D2: Raigad | E2: Maharashtra | F2: India | G2: 18.083 | H2: 73.416 | I2: Essentials | J2: Active | K2: ISO 9001:2015, ISO 14001:2015, ISO 45001:2018 | L2: Yes | M2: 110 | N2: 8500 | O2: Yes | P2: Solvent handling with VOC controls; DG drum yard; firewater ring main. | Q2: 2020-04-01 | R2: Active | S2: Illustrative site master; aligned to annual report commentary on capacity debottlenecking.
A3: LTE | B3: Lote Parshuram Specialty Site | C3: Lote Parshuram | D3: Ratnagiri | E3: Maharashtra | F3: India | G3: 17.85 | H3: 73.225 | I3: Specialties | J3: Active | K3: ISO 9001:2015, ISO 14001:2015, ISO 45001:2018 | L3: Yes | M3: 45 | N3: 2500 | O3: Yes | P3: Fluoro/DG segregation; nitrogen blanketing; low-temp storage (2-8°C) for sensitive inputs. | Q3: 2021-07-01 | R3: Active | S3: Illustrative; aligned to annual report commentary on specialty expansions and compliance.
